<robot name="Jahwin_arm">

  <link name="base_link">
    <visual>
      <origin xyz="0 0 0" rpy="0 0 0" />
      <geometry>
        <mesh filename="package://xarm_description/meshes/link_base.stl" scale="1.0 1.0 1.0"/>
      </geometry>
      <material name="grey">
        <color rgba="0.5 0.5 0.5 1.0"/>
      </material>
    </visual>
  </link>

  <link name="link1">
    <visual>
      <origin xyz="0 0 0" rpy="0 0 0" />
      <geometry>
        <mesh filename="package://xarm_description/meshes/link1.stl" scale="1.0 1.0 1.0"/>
      </geometry>
      <material name="grey">
        <color rgba="0.5 0.5 0.5 1.0"/>
      </material>
    </visual>
  </link>

  <joint name="base_to_link1" type="revolute">
    <origin xyz="0 0 0.356" rpy="0 0 0"/>
    <parent link="base_link"/>
    <child link="link1"/>
    <axis xyz="0 0 1"/>
    <limit lower="-3.1416" upper="3.1416" effort="10" velocity="1.0"/>
  </joint>

<link name="link2">
  <visual>
    <origin xyz="0 0 0" rpy="1.5708 -1.5708 0" />
    <geometry>
      <mesh filename="package://xarm_description/meshes/link2.stl" scale="1.0 1.0 1.0"/>
    </geometry>
    <material name="grey">
      <color rgba="0.5 0.5 0.5 1.0"/>
    </material>
  </visual>
</link>

<joint name="link1_to_link2" type="revolute">
  <origin xyz="0 0 0" rpy="0 0 0"/>
  <parent link="link1"/>
  <child link="link2"/>
  <axis xyz="0 1 0"/>
  <limit lower="-3.1416" upper="3.1416" effort="20" velocity="0.6"/>
</joint>

</robot>
